<?xml version="1.0" encoding="utf-8"?>
<!-- This URDF was automatically created by SolidWorks to URDF Exporter! Originally created by Stephen Brawner (brawner@gmail.com) 
     Commit Version: 1.6.0-1-g15f4949  Build Version: 1.6.7594.29634
     For more information, please see http://wiki.ros.org/sw_urdf_exporter -->
<robot
  name="diffbot">
  <link
    name="base_link">
    <inertial>
      <origin
        xyz="0.0012511 0 -0.02"
        rpy="0 0 0" />
      <mass
        value="7.5332" />
      <inertia
        ixx="0.052212"
        ixy="3.9485E-17"
        ixz="9.6786E-19"
        iyy="0.26506"
        iyz="3.2771E-19"
        izz="0.31524" />
    </inertial>
    <visual>
      <origin
        xyz="0 0 0"
        rpy="0 0 0" />
      <geometry>
        <mesh
          filename="package://diffbot/meshes/base_link.STL" />
      </geometry>
      <material
        name="">
        <color
          rgba="0.52941 0.54902 0.54902 1" />
      </material>
    </visual>
    <collision>
      <origin
        xyz="0 0 0"
        rpy="0 0 0" />
      <geometry>
        <mesh
          filename="package://diffbot/meshes/base_link.STL" />
      </geometry>
    </collision>
  </link>
  <link
    name="linkleft">
    <inertial>
      <origin
        xyz="-1.3878E-17 -0.011048 0"
        rpy="0 0 0" />
      <mass
        value="0.52465" />
      <inertia
        ixx="0.0010699"
        ixy="2.059E-19"
        ixz="-1.6414E-19"
        iyy="0.002062"
        iyz="9.9564E-21"
        izz="0.0010699" />
    </inertial>
    <visual>
      <origin
        xyz="0 0 0"
        rpy="0 0 0" />
      <geometry>
        <mesh
          filename="package://diffbot/meshes/linkleft.STL" />
      </geometry>
      <material
        name="">
        <color
          rgba="0.29804 0.29804 0.29804 1" />
      </material>
    </visual>
    <collision>
      <origin
        xyz="0 0 0"
        rpy="0 0 0" />
      <geometry>
        <mesh
          filename="package://diffbot/meshes/linkleft.STL" />
      </geometry>
    </collision>
  </link>
  <joint
    name="jointleft"
    type="continuous">
    <origin
      xyz="-0.1 0.17 -0.02"
      rpy="0 0 0" />
    <parent
      link="base_link" />
    <child
      link="linkleft" />
    <axis
      xyz="0 -1 0" />
    <limit
      effort="1"
      velocity="1" />
  </joint>
  <link
    name="linkright">
    <inertial>
      <origin
        xyz="1.3878E-17 0.011048 0"
        rpy="0 0 0" />
      <mass
        value="0.52465" />
      <inertia
        ixx="0.0010699"
        ixy="1.4008E-19"
        ixz="1.0434E-35"
        iyy="0.002062"
        iyz="5.8775E-36"
        izz="0.0010699" />
    </inertial>
    <visual>
      <origin
        xyz="0 0 0"
        rpy="0 0 0" />
      <geometry>
        <mesh
          filename="package://diffbot/meshes/linkright.STL" />
      </geometry>
      <material
        name="">
        <color
          rgba="0.29804 0.29804 0.29804 1" />
      </material>
    </visual>
    <collision>
      <origin
        xyz="0 0 0"
        rpy="0 0 0" />
      <geometry>
        <mesh
          filename="package://diffbot/meshes/linkright.STL" />
      </geometry>
    </collision>
  </link>
  <joint
    name="jointright"
    type="continuous">
    <origin
      xyz="-0.1 -0.17 -0.02"
      rpy="0 0 0" />
    <parent
      link="base_link" />
    <child
      link="linkright" />
    <axis
      xyz="0 -1 0" />
    <limit
      effort="1"
      velocity="1" />
  </joint>
</robot>